Workbook

Sheet Geral
H6: Preenchido:
B12: Razão Social 公司名称: | C12: SERVLOG LOGISTICA SERVICOS EM TRANSPORTES LTDA
B13: Nome Fantasia 公司简称: | C13: SERVLOG
B14: CNPJ 公司税号: | C14: 44410871000159 | F14: Inscrição Estadual 州号: | H14: 164196005
B15: Segmento de Mercado 产品类型: | C15: Transportador | G15: CEP Matriz 总部CEP: | H15: 58082000
B16: Endereço 地址: | C16: ROD BR 101 SN KM 88 GALPÃO 28
B17: Bairro 区域: | C17: DISTRITO INDUSTRIAL
B18: Cidade 城市: | C18: JOÃO PESSOA
B19: Estado 州: | C19: PB
B20: Natureza do negócio 业务行业 : | C20: Transporte 承运商 | F20: Documento fiscal 税务类型文件 : | H20: NF-E
B21: Responsável J&T J&T负责人: | C21: ANA CARLA RODRIGUES
B22: Telefone J&T J&T电话号码: | C22: 83999560080 | F22: E-mail J&T J&T邮箱: | H22: anacarla.lucena@jtexpress.com.br
B23: Filial J&T J&T代理区: | C23: Filial PE
B24: Natureza fiscal 税务类型: | C24: Normal
B25: E-mail para XML de Cte 发送XML的CTE邮箱: | C25: leandro2020pessoal@gmail.com - financeiro@servlogpb.com.br -
B26: Tomador do Serviço TOMA值: | C26: Outro | F26: Informações do tomador:

Sheet Comercial
G6: Preenchido:
B12: Nome Contato Comercial 市场部联系人名称: | C12: LEANDRO
B13: E-mail 邮箱: | C13: leandro2020pessoal@gmail.com | F13: Telefone电话号码: | G13: 83999482038
B14: Pedido/Dia Útil (Cliente)订单/工作日(客户): | C14: 80 | F14: Pedido/Dia Útil (J&T)订单/工作日(J&T): | G14: 30
B15: Qtd. Pedidos/Mês (J&T) 货量/月(J&T): | C15: =G14*22 -> 660 | F15: TKT Médio J&T 票均运费: | G15: 18.3
B16: Peso Médio/kg 均重/公斤: | C16: 2
B17: Tier do Cliente no Mercado | C17: F | F17: Tier da Tabela Negociada: | G17: F
B18: Modalidade do Entrega 投递方式: | C18: Standard
B19: Modalidade do Serviço 业务类型: | C19: FALSE | D19: TRUE | E19: TRUE | F19: TRUE | G19: FALSE | H19: FALSE | I19: =COUNTIFS(C19:H19,TRUE) -> 3
C20: Drop off | D20: Last Mile | E20: Coleta CD | F20: Ship From Store | G20: D2D | H20: C2C
B21: Site do Cliente
B22: Nome Completo Representante Legal | C22: LUCINALDO FERREIRA DA SILVA | F22: E-mail Nominal Representante Legal: | G22: financeiro@servlogpb.com.br
B23: Nome Completo Testemunha Contratante | C23: LEANDRO LUIZ LINO | F23: E-mail Nominal Testemunha Contratante | G23: leandro2020pessoal@gmail.com

Sheet Financeiro
D6: Preenchido:
B11: Nome do responsável financeiro: | C11: LEANDRO
B12: E-mail 邮箱: | C12: leandro2020pessoal@gmail.com - financeiro@servlogpb.com.br | D12: Telefone 电话号码: | E12: 83999482038
B13: Endereço: | C13: ROD BR 101 SN - KM 88 GALPÃO 28 - DISTRITO INDUSTRIAL - JOÃO PESSOA PB
B14: Ciclo de Faturamento | C14: Outros (sujeito a aprovação) | D14: Descrever: | E14: QUINZENAL
B15: Prazo de Pagamento | C15: Outros (sujeito a aprovação) | D15: Descrever: | E15: 15
B16: Faturamento de Devolução Separado? | C16: Sim 是
B17: Regras Ressarcimento: | C17: Vigente Conforme Descrito em Contrato
B18: Regras DIFAL: | C18: Vigente Conforme Descrito em Contrato
B19: Nome do responsável pelo reembolso do Difal: | C19: LEANDRO
B20: E-mail 邮箱: | C20: leandro2020pessoal@gmail.com - financeiro@servlogpb.com.br | D20: Telefone 电话号码: | E20: 83999482038
B21: Tipo de Pagamento: | C21: Boleto Itaú | D21: Banco: | E21: BRADESCO
B22: Agência (sem dígito): | C22: 3439 | D22: Conta (com dígito): | E22: 18063-7
B23: Tipo de Conta: | C23: Corrente | D23: Tipo de PIX: | E23: CNPJ
B24: Chave PIX: | C24: 44410871000159

Sheet TI
H6: Preenchido:
B12: Contato do TI IT联系人: | C12: JOAO LEONARDO RODRIGUES
B13: E-mail 邮箱: | C13: jlgiovanetti@gmail.com | F13: Telefone 电话号码: | H13: 44 98807-6116
B14: Modelo de Integração 对接方式: | C14: Plataforma
B15: Nome da Plataforma 平台名称: | C15: ENVIO LEGAL | G15: API KEY:
B16: E-mail para envio do XML XML发送的电子邮 :
B18: Id JMS: | H18: Senha 密码 :
B19: Pedidos Multiplos一票多件?
B20: É multiorigem? 是否為多始發地
B21: Possibilidade de pedidos acima de 30Kg? 订单是否超过30 KG?
B22: Outros cadastros do Grupo 是否有其他公司税号注册(子公司):
B34: Cenário de negócios 业务场景 | C34: RESPOSTAS | F34: Informações do cliente 客户信息 | I34: RESPOSTAS
B35: Descrição do cliente (apresentação) / 客户描述（背景介绍）
B36: 业务模式（仓配/D2D/C2C） Modelo de negócios (PA/D2D/C2C) | F36: 客户名称（******） Nome do cliente | I36: =Geral!C12 -> SERVLOG LOGISTICA SERVICOS EM TRANSPORTES LTDA
B37: 税务类型文件（NFE/NFS-e/CTE/DC） Documento fiscal enviado pelo cliente （NFE/NFS-e/CTE/DC） | C37: =Geral!H20 -> NF-E | F37: 客户编码（******） Código do cliente | I37: =C18 -> 0
B38: 客户类型（独立站/电商平台/客户集成平台） Tipo de cliente (Site independente/Marketplace/Plataforma de integração de clientes) | F38: 所属行业（服饰/电器/宠物用品...） Setor (têxtil/eletrônicos/pet...) | I38: =Geral!C15 -> Transportador
B39: 业务类型（普通单/一票多件） Tipo de negócio (Pedido unitário/múltiplo) | C39: =IF(C19="Sim 是","Pedido Unitario 普通单 / Pedido Multiplo 一票多件 ","Pedido Unitario 普通单 ") -> Pedido Unitario 普通单 | F39: 业务行业（贸易/工业/承运商/） Natureza do negócio (comércio/indústria/transporte) | I39: =Geral!C20 -> Transporte 承运商
B40: 运单号规则（一票多件单号/普通单号） Regras de criação de nº de pedido JMS (nº unitário/nº múltiplo) | C40: =IF(C39="Pedido Unitario 普通单 / Pedido Multiplo 一票多件 ","nº unitário 一票多件单号 /nº múltiplo 普通单号","nº unitário 一票多件单号") -> nº unitário 一票多件单号 | F40: CNPJ（******） | I40: =Geral!C14 -> 44410871000159
B41: 收件人类型（CNPJ/CPF） Tipo de destinatário （CNPJ/CPF） | F41: IE（******） | I41: =Geral!H14 -> 164196005
B42: 收件人类型CNPJ（有IE/无IE） Se destinatário CNPJ (com IE/sem IE) | F42: 商务端联系人（姓名/联系电话/邮箱） Contato comercial (Nome/Telefone/E-mail) | I42: =Geral!H22 -> anacarla.lucena@jtexpress.com.br
B43: 面单操作（换单/生成J&T面单） Operação de etiqueta (troca de etiqueta/smartlabel) | F43: 技术端联系人（姓名/联系电话/邮箱） Contato técnico (Nome/Telefone/E-mail) | I43: =C13 -> jlgiovanetti@gmail.com
B44: 重量校验限制（0,01—35kg） Limites de peso （0,01—35kg） | C44: =IF(C21="Não 否","0,01KG - 30,00KG","0,01KG - 35,00KG") -> 0,01KG - 35,00KG
B45: 服务类型（Drop off/pick up） Tipo de serviço （Drop off/pick up） | C45: =Geral!C24 -> Normal | F45: 收件地址 Endereço de coleta | I45: =Geral!C16 -> ROD BR 101 SN KM 88 GALPÃO 28
B46: 调度方式（邮编调度/客户资料调度） Tipo de agendamento (por CEP/ por material do cliente) | F46: 退件地址 Endereço de devolução | I46: =Operações!C41 -> ROD BR 101 SN - KM 88 GALPÃO 28
B47: 订单取消（是/否） Integração de cancelamento de pedido? (Sim/Não) | F47: 账期类型（15天/30天） Tipo de fechamento (15 dias/30 dias)
B48: 轨迹映射（客户映射J&T/J&T映射客户） Integração de status (Cliente reflete status da J&T/J&T reflete status do cliente) | C48: =IF(C17="j&t EXPRESS","Cliente reflete status da J&T 客户映射J&T","J&T reflete status do cliente J&T映射客户") -> J&T reflete status do cliente J&T映射客户 | F48: TOMA信息（客户/寄件人/收件人.....) Informações TOMA (Cliente/Remetente/Destinatário...) | I48: =Geral!C26 -> Outro
B49: 问题件映射（客户映射J&T/J&T映射客户） Integração de ocorrências (pacotes problemáticos) (Cliente reflete status da J&T/J&T reflete status do cliente) | C49: =IF(C17="j&t EXPRESS","Cliente reflete status da J&T 客户映射J&T","J&T reflete status do cliente J&T映射客户") -> J&T reflete status do cliente J&T映射客户 | F49: 计费重量（订单重量/入仓重量/.....） Peso faturável (peso do pacote/peso de entrada em armazém...)
B50: 快件类型（EZ） Tipo de remessa (EZ) | C50: EZ | F50: 日均件量 Volume diário | I50: =Comercial!G14 -> 30
B51: 收件人地址规则（******） Regras de endereço de destinatário | F51: 货物流向 Destino de pedidos (%região)
B52: 收件人手机号码（******） Número de celular do destinatário é enviado? | F52: 货物均重 Média de peso | I52: =Comercial!C16 -> 2

Sheet Operações
H6: Preenchido:
B12: DANFE em Janela Fixada 发票(DANFE)贴在包裹表面: | C12: Sim 是 | F12: Produto Frágil易碎品: | I12: Não 否
B14: ORIGENS DAS COLETAS
B15: Endereço para Coleta 揽收地址: | C15: ROD BR 101 SN - KM 88 GALPÃO 28
B16: Cidade: | C16: JOÃO PESSOA | D16: Bairro: | E16: DISTRITO INDUSTRIAL | F16: UF: | G16: PB | H16: CEP: | I16: 58082-000
B17: Nome responsável no cliente: | C17: LEANDRO | E17: Telefone: | H17: E-mail:
B18: Média volume dia: | C18: 5 | E18: Peso médio: | F18: 3 | H18: Valor NF médio:
B19: Tipo de coleta 服务类型: | C19: Coleta no cliente上門取件
B20: Periodicidade: | C20: De segunda a sexta | F20: Horário: | H20: A combinar
B21: Horário para coleta 揽收时间: | C21: a combinar | E21: Frequência da coleta 揽收次数: | H21: Diaria
B24: DESTINOS DOS PEDIDOS
B25: Abrangência Nacional J&T: | C25: Sim | F25: Inicialmente UFs: | H25: Todas
B26: Somente UFs (descrever)
B28: FILIAL RESPONSÁVEL PARA REALIZAR A COLETA
B29: Responsável J&T (Transporte): | C29: Barueri | E29: Telefone: | H29: E-mail:
B31: PARTICULARIDADES PARA REALIZAR COLETA NO CLIENTE
B32: Haverá PA? | C32: Sim 是 | D32: Particularidades do PA:
B34: PARTICULARIDADES PARA REALIZAR COLETA NO CLIENTE
B38: DEVOLUÇÕES
B40: ENDEREÇO DE DEVOLUÇÃO
B41: Endereço: | C41: ROD BR 101 SN - KM 88 GALPÃO 28
B42: Bairro: | C42: DISTRITO INDUSTRIAL | D42: Cidade: | E42: JOÃO PESSOA | F42: UF: | G42: PB | H42: Cep: | I42: 58082-000
B43: Nome responsável no cliente: | C43: LEANDRO | E43: Telefone: | H43: E-mail:
B44: Responsável J&T (Transporte): | E44: Telefone: | H44: E-mail:
B45: Periodicidade: | C45: Diaria | E45: Sábado: | F45: Não | H45: Domingo: | I45: Não
B46: Horário: | C46: A combinar
B48: AGENDAMENTO DAS DEVOLUÇÕES
B49: Necessidade de agendamento? | C49: Sim
B50: Responsável no cliente: | C50: Robson Pereira | D50: Tel.: | G50: E-mail:
B51: Periodicidade (grades):
B52: Capacidade de volumes para receber:
B53: Aproveitamento da coleta?
B54: Responsável na J&T: | D54: Tel.: | G54: E-mail:
B55: Obs - Grau de avaria aceitável
B57: FILIAL RESPONSÁVEL PARA REALIZAR A DEVOLUÇÃO
B58: Responsável J&T (Transporte): | C58: Vanilson | E58: Telefone: | F58: 11 97352-8892 | H58: E-mail: | I58: vanilson.silva@jtexpress.com.br
B60: PARTICULARIDADES PARA REALIZAR DEVOLUÇÃO NO CLIENTE

Sheet CX
H6: Preenchido:
B13: ANALISTA J&T RESPONSÁVEL PELO ATENDIMENTO
B14: Nome analista: | E14: Telefone: | G14: E-mail:
B15: Supervisor: | E15: Telefone: | G15: E-mail:
B16: Gerente: | E16: Telefone: | G16: E-mail:
B18: CONTATOS CLIENTE TRATATIVA (ATENDIMENTO)
B19: Nome | D19: Função | F19: Fone | H19: E-mail
B24: CONTATOS CLIENTE TRATATIVA (RESSARCIMENTO)
B25: Nome | D25: Função | F25: Fone | H25: E-mail
B30: PRAZOS ATENDIMENTO
B31: Indicador | C31: Meta | D31: Métrica | E31: Descrição da Regra
B32: Prazo retorno reclamação
B33: Prazo retorno PNR
B34: SLA de reclamação
B35: SLA de Entrega
B36: SLA de Insucesso
B37: SLA de ressarcimento

Sheet Apoio
B1: Listas >> | L1: Cálculos Progresso >> | Q1: Obrigatorias (X) >> | R1: Pontos Opcionais: | S1: 0.1 | U1: Pontos Redução: | V1: -0.5
Q2: Itens | R2: Mínimo X | S2: Peso X | T2: Embalagens Primárias | U2: Caixa Secundária | V2: Plástico bolha | W2: Sacos de ar | X2: Isopor | Y2: Jornal | Z2: Fita adesiva antiviolação | AA2: Contém adesivo explicativo | AB2: Etiqueta resistente | AC2: Caixa de Papelão Reforçada | AD2: Mercadoria Desmontada | AE2: Flayer/Saco descaracterizando a marca
B3: Segmento de mercado | D3: Modalidade de Entrega | F3: UF | H3: Tier | J3: Formato Indenização | L3: Página | M3: Qtd Campos | N3: Qtd Preenchida | O3: % Alcance | Q3: 1. Aparelhos de telefonia celular, tablets e acessórios: | R3: 2 | S3: =1/R3 -> 0.5 | U3: x | V3: x | W3: x | X3: x
B4: Intermediador | D4: Standard | F4: AC | H4: A+ | J4: AWB | L4: Geral | M4: 20 | N4: =COUNTA(Geral!C12,Geral!C13,Geral!C14,Geral!H14,Geral!C15,Geral!H15,Geral!C16,Geral!C17,Geral!C18,Geral!C19,Geral!C20,Geral!H20,Geral!C21,Geral!C22,Geral!H22,Geral!C23,Geral!C24,Geral!C25,Geral!C26,Geral!H26) -> 19 | O4: =N4/M4 -> 0.95 | Q4: 2. Aparelhos eletrônicos de som e imagem: | R4: 2 | S4: =1/R4 -> 0.5 | U4: x | V4: x | W4: x | X4: x
B5: Alimentos e Bebidas | D5: Expresso | F5: AL | H5: A | J5: N° do Pedido | L5: Comercial | M5: 16 | N5: =COUNTA(Comercial!C12,Comercial!C13,Comercial!G13,Comercial!C14,Comercial!G14,Comercial!G15,Comercial!C16,Comercial!C17,Comercial!G17,Comercial!C18,Comercial!C21,Comercial!C22,Comercial!C23,Comercial!G22,Comercial!G23)+IF(Comercial!I19>0,1,0) -> 15 | O5: =N5/M5 -> 0.9375 | Q5: 3. Computadores, gabinetes, peças e periféricos: | R5: 3 | S5: =1/R5 -> 0.33333333 | U5: x | V5: x | X5: x | AA5: x
B6: Arte e Antiguidades | D6: Personalizado | F6: AM | H6: B | J6: DANFE | L6: Financeiro | M6: =19 + IF(Financeiro!C14="Outros (sujeito a aprovação)",1,0) + IF(Financeiro!C15="Outros (sujeito a aprovação)",1,0) -> 21 | N6: =COUNTA(Financeiro!C11,Financeiro!C12,Financeiro!E12,Financeiro!C13,Financeiro!C14,Financeiro!C15,Financeiro!C16,Financeiro!C17,Financeiro!C18,Financeiro!C19,Financeiro!C20,Financeiro!E20,Financeiro!C21,Financeiro!E21,Financeiro!C22,Financeiro!E22,Financeiro!C23,Financeiro!E23,Financeiro!C24) + IF(AND(Financeiro!C14="Outros (sujeito a aprovação)",Financeiro!E14<>""),1,0) + IF(AND(Financeiro!C15="Outros (sujeito a aprovação)",Financeiro!E15<>""),1,0) -> 21 | O6: =N6/M6 -> 1 | Q6: 4. Eletrodomésticos ou Eletroportáveis | R6: 3 | S6: =1/R6 -> 0.33333333 | U6: x | V6: x | X6: x | AA6: x
B7: Artigos Religiosos | F7: AP | H7: C | J7: ID do Cliente | L7: Operações | M7: 57 | N7: =COUNTA(Operações!C12,Operações!I12,Operações!C15,Operações!C16,Operações!E16,Operações!G16,Operações!I16,Operações!C17,Operações!F17,Operações!I17,Operações!I18,Operações!F18,Operações!C18,Operações!C19,Operações!C20,Operações!H20,Operações!H21,Operações!C21,Operações!C25,Operações!H25,Operações!C26,Operações!C29,Operações!F29,Operações!I29,Operações!F32,Operações!C32,Operações!B35,Operações!C41,Operações!C42,Operações!E42,Operações!G42,Operações!I42,Operações!C43,Operações!F43,Operações!I43,Operações!C44,Operações!F44,Operações!I44,Operações!C45,Operações!F45,Operações!I45,Operações!C46,Operações!C49,Operações!C50,Operações!E50,Operações!H50,Operações!C51,Operações!C52,Operações!C53,Operações!C54,Operações!E54,Operações!H54,Operações!C55,Operações!C58,Operações!F58,Operações!I58,Operações!B61) -> 34 | O7: =N7/M7 -> 0.59649123 | Q7: 5. Artigos de higiene: | R7: 2 | S7: =1/R7 -> 0.5 | T7: x | AA7: x
B8: Automóveis e Veículos | F8: BA | H8: D | L8: Customer Success | M8: 35 | N8: =COUNTA(CX!C14:D16,CX!F14:F16,CX!H14:I16,CX!B20:I20,CX!B26:I26,CX!C32:E37) -> 0 | O8: =N8/M8 -> 0 | Q8: 6. Cosméticos e perfumes | R8: 2 | S8: =1/R8 -> 0.5 | T8: x | AA8: x
B9: Bebês e Cia | F9: CE | H9: E | L9: TI | M9: =IF(TI!C14 = "Plataforma",25,23) -> 25 | N9: =COUNTA(TI!C12,TI!C13,TI!H13,TI!C14,TI!C16,TI!C18,TI!I18,TI!C19,TI!C20,TI!C21,TI!C22,TI!C36,TI!C38,TI!C41,TI!C42,TI!C43,TI!C46,TI!C47,TI!C51,TI!C52,TI!I47,TI!I49,TI!I51)+IF(TI!C14="Plataforma",COUNTA(TI!C15,TI!H15),0) -> 5 | O9: =IF(N9/M9 > 1,1, N9/M9) -> 0.2 | Q9: 7. Lâminas e aparelhos de barbear: | R9: 2 | S9: =1/R9 -> 0.5 | T9: x | X9: x
B10: Brindes / Materiais Promocionais | F10: DF | H10: F | Q10: 8. Medicamentos, vitaminas e suplementos: | R10: 2 | S10: =1/R10 -> 0.5 | AA10: x
B11: Brinquedos e Games | F11: ES | J11: Normal | Q11: 9. Autopeças: | R11: 2 | S11: =1/R11 -> 0.5 | U11: x | AA11: x
B12: Casa e Decoração | F12: GO | H12: Sim/Não | J12: Redespacho | Q12: 10. Pneus e câmaras de ar: | R12: 1 | S12: =1/R12 -> 1 | AB12: x
B13: Colecionáveis | F13: MA | H13: Sim 是 | J13: Subcontratação | Q13: 11. Biciletas: | R13: 2 | S13: =1/R13 -> 0.5 | AC13: x | AD13: x
B14: Construção e Ferramentas | F14: MG | H14: Não 否 | L14: Pagamento DIFAL | Q14: 12. Brinquedos em Geral: | R14: 2 | S14: =1/R14 -> 0.5 | T14: x | V14: x | W14: x
B15: Cosméticos e Perfumaria | F15: MS | H15: Parcial | L15: Pagamento realizado pela J&T e ressarcido ao final do mês pelo embarcador | Q15: 13. Balas, chocolates, chicletes e doces em geral: | R15: 1 | S15: =1/R15 -> 1 | T15: x | U15: x | AA15: x
B16: Cursos e Educação | F16: MT | H16: Tipo Pgto | Q16: 14. Café (qualquer tipo): | R16: 2 | S16: =1/R16 -> 0.5 | T16: x | U16: x | AA16: x
B17: Eletrodomésticos | F17: PA | H17: Mensal | Q17: 15. Roupas, confecções, fios têxteis e tecidos: | R17: 2 | S17: =1/R17 -> 0.5 | T17: x | U17: x | AE17: x
B18: Eletrônicos | F18: PB | H18: Quinzenal | J18: Seguro e PGR | Q18: 16. Calçados: | R18: 2 | S18: =1/R18 -> 0.5 | T18: x | AE18: x
B19: Esporte e Lazer | F19: PE | J19: Próprio | Q19: 17. Relógios e Jóias: | R19: 3 | S19: =1/R19 -> 0.33333333 | U19: x | V19: x | W19: x | X19: x | Z19: x | AA19: x
B20: Festas / Eventos | F20: PI | H20: Tipo Frete | J20: J&T Express | Q20: 18. Produtos de limpeza: | R20: 2 | S20: =1/R20 -> 0.5 | U20: x | AA20: x
B21: Gráficos / Editoriais | F21: PR | H21: NF-e | Q21: 19. Produtos veterinários: | R21: 3 | S21: =1/R21 -> 0.33333333 | U21: x | V21: x | W21: x | X21: x | AA21: x
B22: Instrumentos Musicais | F22: RJ | H22: CTE | J22: Item Integração | Q22: 20. Lâmpadas, reatores, luminárias e periféricos: | R22: 3 | S22: =1/R22 -> 0.33333333 | U22: x | V22: x | W22: x | X22: x | AA22: x
B23: Joalheria | F23: RN | J23: EDI com retorno | Q23: 21. Vidros em Geral: | R23: 3 | S23: =1/R23 -> 0.33333333 | U23: x | V23: x | W23: x | X23: x | AA23: x
B24: Livros | F24: RO | H24: Forma Pgto | J24: EDI sem retorno | Q24: 22. Fios e Cabos Elétricos: | R24: 2 | S24: =1/R24 -> 0.5 | U24: x | AA24: x
B25: Medicamentos | F25: RR | H25: Boleto | J25: API Cliente | Q25: 23. Livros, Revistas e Papelaria em Geral | R25: 1 | S25: =1/R25 -> 1 | T25: x | V25: x
B26: Moda e Acessórios | F26: RS | H26: Depósito em Conta | J26: API J&T
B27: Óticas | F27: SC | J27: XML
B28: Papelaria e Escritório | F28: SE | H28: Regime Trib. | J28: Plataforma
B29: Pet Shop | F29: SP | H29: Lucro Real | J29: Vip | Q29: Filial
B30: Sex Shop | F30: TO | H30: Lucro Presumido | Q30: Filial AM
B31: Tabacaria | H31: Simples Nacional | J31: GRIS | Q31: Filial BA
B32: Transportador | J32: Padrão | Q32: Filial CE
B33: Turismo | H33: Prazo Vcto. | J33: Personalizado Conforme Tabela | Q33: Filial GO
H34: 15 dias | Q34: Filial MA
H35: 30 dias | Q35: Filial MG
Q36: Filial MT
H37: Características da Operação: | J37: Formato Indenização | Q37: Filial PA
H38: Normal | J38: Depósito em conta | Q38: Filial PE
H39: Subcontratação | J39: Abatimento Fatura | Q39: Filial PR
H40: Redespacho | Q40: Filial RJ
...
